Workbook

Sheet Mercury
A2: Date (UTC) | B2: Description | C2: Amount | D2: Status | E2: Source Account | F2: Bank Description | G2: Reference | H2: Note | I2: Last Four Digits | J2: Name On Card | K2: Mercury Category | L2: Category | M2: Source of Category | N2: GL Code | O2: Source of GL Code | P2: Timestamp | Q2: Original Currency | R2: Check Number | S2: Tags | T2: Cardholder Email | U2: Tracking ID | V2: Failure Reason | W2: Failure Reason | X2: Year (real) | Y2: Year (allocated) | Z2: Month (real) | AA2: Month (allocated) | AB2: Quarter | AC2: Statement | AD2: Type 1 | AE2: Type 2 | AF2: Type 2_B | AG2: Type 3 | AH2: Type 4 for checking flows (no edits) | AI2: Type 4 (edited)
A3: 31/08/26 | B3: Mercury IO Cashback | C3: 131.38 | D3: Sent | E3: Welcome to Column N.A. (Mercury Checking xx5998) | P3: ############ | X3: 2026 | Y3: 2026 | Z3: 8 | AA3: 8 | AB3: 3 | AC3: =VLOOKUP($B3,Dictionary_v2!$B:$E,2,0) -> P&L | AD3: Recurring | AE3: =VLOOKUP($B3,Dictionary_v2!$B:$E,3,0) -> 2. Candidates Sourcing | AF3: =VLOOKUP(AE3,Dictionary_v2!R:S,2,0) -> 2. Candidates Sourcing | AG3: =VLOOKUP($B3,Dictionary_v2!$B:$E,4,0) -> 1. Social Media | AH3: =if(C3>0,"In","Out") -> In | AI3: =if(C3>0,"In","Out") -> In
A4: 31/08/26 | B4: Welcome to Column N.A. (Mercury Checking xx5998) | C4: 8777.25 | D4: Sent | E4: Mercury Credit | F4: IO AUTOPAY | P4: ############ | X4: 2026 | Y4: 2026 | Z4: 8 | AA4: 8 | AB4: 3 | AC4: =VLOOKUP($B4,Dictionary_v2!$B:$E,2,0) -> Intercompany | AD4: Recurring | AE4: =VLOOKUP($B4,Dictionary_v2!$B:$E,3,0) | AG4: =VLOOKUP($B4,Dictionary_v2!$B:$E,4,0) | AH4: =if(C4>0,"In","Out") -> In | AI4: =if(C4>0,"In","Out") -> In
A5: 31/08/26 | B5: Mercury Credit | C5: -8777.25 | D5: Sent | E5: Welcome to Column N.A. (Mercury Checking xx5998) | F5: IO AUTOPAY | P5: ############ | X5: 2026 | Y5: 2026 | Z5: 8 | AA5: 8 | AB5: 3 | AC5: =VLOOKUP($B5,Dictionary_v2!$B:$E,2,0) -> Intercompany | AD5: Recurring | AE5: =VLOOKUP($B5,Dictionary_v2!$B:$E,3,0) | AG5: =VLOOKUP($B5,Dictionary_v2!$B:$E,4,0) | AH5: =if(C5>0,"In","Out") -> Out | AI5: =if(C5>0,"In","Out") -> Out
A6: 30/08/26 | B6: Anthropic | C6: -90.02 | D6: Sent | E6: Mercury Credit | F6: ANTHROPIC | I6: 3684 | J6: Ivan Amelong | K6: Software | P6: ############ | Q6: USD | T6: i@nexiu.ai | X6: 2026 | Y6: 2026 | Z6: 8 | AA6: 8 | AB6: 3 | AC6: =VLOOKUP($B6,Dictionary_v2!$B:$E,2,0) -> P&L | AD6: Recurring | AE6: =VLOOKUP($B6,Dictionary_v2!$B:$E,3,0) -> 3. Platform | AF6: =VLOOKUP(AE6,Dictionary_v2!R:S,2,0) -> 3. Platform | AG6: =VLOOKUP($B6,Dictionary_v2!$B:$E,4,0) -> 1. Variable | AH6: =if(C6>0,"In","Out") -> Out | AI6: =if(C6>0,"In","Out") -> Out
A7: 28/08/26 | B7: Facebook | C7: -48.95 | D7: Sent | E7: Mercury Credit | F7: FACEBK *YEGWTY9E92 | I7: 2489 | J7: Ivan Amelong | K7: Advertising | P7: ############ | Q7: USD | T7: i@nexiu.ai | X7: 2026 | Y7: 2026 | Z7: 8 | AA7: 8 | AB7: 3 | AC7: =VLOOKUP($B7,Dictionary_v2!$B:$E,2,0) -> P&L | AD7: Recurring | AE7: =VLOOKUP($B7,Dictionary_v2!$B:$E,3,0) -> 2. Candidates Sourcing | AF7: =VLOOKUP(AE7,Dictionary_v2!R:S,2,0) -> 2. Candidates Sourcing | AG7: =VLOOKUP($B7,Dictionary_v2!$B:$E,4,0) -> 1. Social media | AH7: =if(C7>0,"In","Out") -> Out | AI7: =if(C7>0,"In","Out") -> Out
A8: 27/08/26 | B8: Ivan Amelong - Wise (Ivan Amelong) | C8: -5500 | D8: Sent | E8: Welcome to Column N.A. (Mercury Checking xx5998) | F8: Send Money transaction initiated on Mercury | G8: From Nexiu AI, LLC via mercury.com | P8: ############ | U8: 121145431611741 | X8: 2026 | Y8: 2026 | Z8: 8 | AA8: 8 | AB8: 3 | AC8: =VLOOKUP($B8,Dictionary_v2!$B:$E,2,0) -> P&L | AD8: Recurring | AE8: =VLOOKUP($B8,Dictionary_v2!$B:$E,3,0) -> 7. Founders | AF8: =VLOOKUP(AE8,Dictionary_v2!R:S,2,0) -> 6. Other fixed and admin | AG8: =VLOOKUP($B8,Dictionary_v2!$B:$E,4,0) -> 1. Salaries | AH8: =if(C8>0,"In","Out") -> Out | AI8: =if(C8>0,"In","Out") -> Out
A9: 27/08/26 | B9: Fede (BoA) (Federico David Naides) | C9: -5500 | D9: Sent | E9: Welcome to Column N.A. (Mercury Checking xx5998) | F9: Send Money transaction initiated on Mercury | G9: From Nexiu AI, LLC | P9: ############ | U9: rttr_3IVRYnxSyk0ARsTrjLezShg08Br | X9: 2026 | Y9: 2026 | Z9: 8 | AA9: 8 | AB9: 3 | AC9: =VLOOKUP($B9,Dictionary_v2!$B:$E,2,0) -> P&L | AD9: Recurring | AE9: =VLOOKUP($B9,Dictionary_v2!$B:$E,3,0) -> 7. Founders | AF9: =VLOOKUP(AE9,Dictionary_v2!R:S,2,0) -> 6. Other fixed and admin | AG9: =VLOOKUP($B9,Dictionary_v2!$B:$E,4,0) -> 1. Salaries | AH9: =if(C9>0,"In","Out") -> Out | AI9: =if(C9>0,"In","Out") -> Out
A10: 27/08/26 | B10: Intl. Wire Fee | C10: -15 | D10: Sent | E10: Welcome to Column N.A. (Mercury Checking xx5998) | F10: OUR fee for international wire | P10: ############ | X10: 2026 | Y10: 2026 | Z10: 8 | AA10: 8 | AB10: 3 | AC10: =VLOOKUP($B10,Dictionary_v2!$B:$E,2,0) -> P&L | AD10: Recurring | AE10: =VLOOKUP($B10,Dictionary_v2!$B:$E,3,0) -> 3. Platform | AF10: =VLOOKUP(AE10,Dictionary_v2!R:S,2,0) -> 3. Platform | AG10: =VLOOKUP($B10,Dictionary_v2!$B:$E,4,0) -> 2. Fixed | AH10: =if(C10>0,"In","Out") -> Out | AI10: =if(C10>0,"In","Out") -> Out
A11: 27/08/26 | B11: Efren (Ecuador) (Efren Rogelio Narvaez Peña) | C11: -5000 | D11: Sent | E11: Welcome to Column N.A. (Mercury Checking xx5998) | F11: Send Money transaction initiated on Mercury | G11: From Nexiu AI LLC | P11: ############ | X11: 2026 | Y11: 2026 | Z11: 8 | AA11: 8 | AB11: 3 | AC11: =VLOOKUP($B11,Dictionary_v2!$B:$E,2,0) -> P&L | AD11: Recurring | AE11: =VLOOKUP($B11,Dictionary_v2!$B:$E,3,0) -> 7. Founders | AF11: =VLOOKUP(AE11,Dictionary_v2!R:S,2,0) -> 6. Other fixed and admin | AG11: =VLOOKUP($B11,Dictionary_v2!$B:$E,4,0) -> 1. Salaries | AH11: =if(C11>0,"In","Out") -> Out | AI11: =if(C11>0,"In","Out") -> Out
A12: 27/08/26 | B12: Welcome to Column N.A. (Mercury Checking xx5998) | C12: -11585.8 | D12: Sent | E12: Mercury Checking xx0301 | F12: Transfer between your Mercury accounts | P12: ############ | X12: 2026 | Y12: 2026 | Z12: 8 | AA12: 8 | AB12: 3 | AC12: =VLOOKUP($B12,Dictionary_v2!$B:$E,2,0) -> Intercompany | AD12: Recurring | AE12: =VLOOKUP($B12,Dictionary_v2!$B:$E,3,0) | AG12: =VLOOKUP($B12,Dictionary_v2!$B:$E,4,0) | AH12: =if(C12>0,"In","Out") -> Out | AI12: =if(C12>0,"In","Out") -> Out
A13: 27/08/26 | B13: Mercury Checking xx0301 | C13: 11585.8 | D13: Sent | E13: Welcome to Column N.A. (Mercury Checking xx5998) | F13: Transfer between your Mercury accounts | P13: ############ | X13: 2026 | Y13: 2026 | Z13: 8 | AA13: 8 | AB13: 3 | AC13: =VLOOKUP($B13,Dictionary_v2!$B:$E,2,0) -> Intercompany | AD13: Recurring | AE13: =VLOOKUP($B13,Dictionary_v2!$B:$E,3,0) | AG13: =VLOOKUP($B13,Dictionary_v2!$B:$E,4,0) | AH13: =if(C13>0,"In","Out") -> In | AI13: =if(C13>0,"In","Out") -> In
A14: 27/08/26 | B14: Welcome to Column N.A. (Mercury Checking xx5998) | C14: -19000 | D14: Sent | E14: Treasury | F14: Liquidation of Treasury assets | P14: ############ | U14: 20260827B1Q8154C326164 | X14: 2026 | Y14: 2026 | Z14: 8 | AA14: 8 | AB14: 3 | AC14: =VLOOKUP($B14,Dictionary_v2!$B:$E,2,0) -> Intercompany | AD14: Recurring | AE14: =VLOOKUP($B14,Dictionary_v2!$B:$E,3,0) | AG14: =VLOOKUP($B14,Dictionary_v2!$B:$E,4,0) | AH14: =if(C14>0,"In","Out") -> Out | AI14: =if(C14>0,"In","Out") -> Out
A15: 27/08/26 | B15: Treasury | C15: 19000 | D15: Sent | E15: Welcome to Column N.A. (Mercury Checking xx5998) | F15: Liquidation of Treasury assets | P15: ############ | U15: 20260827B1Q8154C326164 | X15: 2026 | Y15: 2026 | Z15: 8 | AA15: 8 | AB15: 3 | AC15: =VLOOKUP($B15,Dictionary_v2!$B:$E,2,0) -> Intercompany | AD15: Recurring | AE15: =VLOOKUP($B15,Dictionary_v2!$B:$E,3,0) | AG15: =VLOOKUP($B15,Dictionary_v2!$B:$E,4,0) | AH15: =if(C15>0,"In","Out") -> In | AI15: =if(C15>0,"In","Out") -> In
A16: 27/08/26 | B16: Anthropic | C16: -90.02 | D16: Sent | E16: Mercury Credit | F16: ANTHROPIC | I16: 3684 | J16: Ivan Amelong | K16: Software | P16: ############ | Q16: USD | T16: i@nexiu.ai | X16: 2026 | Y16: 2026 | Z16: 8 | AA16: 8 | AB16: 3 | AC16: =VLOOKUP($B16,Dictionary_v2!$B:$E,2,0) -> P&L | AD16: Recurring | AE16: =VLOOKUP($B16,Dictionary_v2!$B:$E,3,0) -> 3. Platform | AF16: =VLOOKUP(AE16,Dictionary_v2!R:S,2,0) -> 3. Platform | AG16: =VLOOKUP($B16,Dictionary_v2!$B:$E,4,0) -> 1. Variable | AH16: =if(C16>0,"In","Out") -> Out | AI16: =if(C16>0,"In","Out") -> Out
A17: 27/08/26 | B17: Facebook | C17: -985 | D17: Sent | E17: Mercury Credit | F17: FACEBK *Y4CTA26GV4 | I17: 2489 | J17: Ivan Amelong | K17: Advertising | P17: ############ | Q17: USD | T17: i@nexiu.ai | X17: 2026 | Y17: 2026 | Z17: 8 | AA17: 8 | AB17: 3 | AC17: =VLOOKUP($B17,Dictionary_v2!$B:$E,2,0) -> P&L | AD17: Recurring | AE17: =VLOOKUP($B17,Dictionary_v2!$B:$E,3,0) -> 2. Candidates Sourcing | AF17: =VLOOKUP(AE17,Dictionary_v2!R:S,2,0) -> 2. Candidates Sourcing | AG17: =VLOOKUP($B17,Dictionary_v2!$B:$E,4,0) -> 1. Social media | AH17: =if(C17>0,"In","Out") -> Out | AI17: =if(C17>0,"In","Out") -> Out
A18: 27/08/26 | B18: Facebook | C18: -10 | D18: Sent | E18: Mercury Checking xx0301 | F18: FACEBK *8SHQA26GV4 | I18: 9824 | J18: Ivan Amelong | K18: Advertising | P18: ############ | Q18: USD | T18: i@nexiu.ai | X18: 2026 | Y18: 2026 | Z18: 8 | AA18: 8 | AB18: 3 | AC18: =VLOOKUP($B18,Dictionary_v2!$B:$E,2,0) -> P&L | AD18: Recurring | AE18: =VLOOKUP($B18,Dictionary_v2!$B:$E,3,0) -> 2. Candidates Sourcing | AF18: =VLOOKUP(AE18,Dictionary_v2!R:S,2,0) -> 2. Candidates Sourcing | AG18: =VLOOKUP($B18,Dictionary_v2!$B:$E,4,0) -> 1. Social media | AH18: =if(C18>0,"In","Out") -> Out | AI18: =if(C18>0,"In","Out") -> Out
A19: 27/08/26 | B19: Facebook | C19: -343.37 | D19: Sent | E19: Mercury Checking xx0301 | F19: FACEBK *7FAR73EGV4 | I19: 9824 | J19: Ivan Amelong | K19: Advertising | P19: ############ | Q19: USD | T19: i@nexiu.ai | X19: 2026 | Y19: 2026 | Z19: 8 | AA19: 8 | AB19: 3 | AC19: =VLOOKUP($B19,Dictionary_v2!$B:$E,2,0) -> P&L | AD19: Recurring | AE19: =VLOOKUP($B19,Dictionary_v2!$B:$E,3,0) -> 2. Candidates Sourcing | AF19: =VLOOKUP(AE19,Dictionary_v2!R:S,2,0) -> 2. Candidates Sourcing | AG19: =VLOOKUP($B19,Dictionary_v2!$B:$E,4,0) -> 1. Social media | AH19: =if(C19>0,"In","Out") -> Out | AI19: =if(C19>0,"In","Out") -> Out
A20: 27/08/26 | B20: Facebook | C20: -4 | D20: Sent | E20: Mercury Credit | F20: FACEBK *J992W5JAR4 | I20: 3684 | J20: Ivan Amelong | K20: Advertising | P20: ############ | Q20: USD | T20: i@nexiu.ai | X20: 2026 | Y20: 2026 | Z20: 8 | AA20: 8 | AB20: 3 | AC20: =VLOOKUP($B20,Dictionary_v2!$B:$E,2,0) -> P&L | AD20: Recurring | AE20: =VLOOKUP($B20,Dictionary_v2!$B:$E,3,0) -> 2. Candidates Sourcing | AF20: =VLOOKUP(AE20,Dictionary_v2!R:S,2,0) -> 2. Candidates Sourcing | AG20: =VLOOKUP($B20,Dictionary_v2!$B:$E,4,0) -> 1. Social media | AH20: =if(C20>0,"In","Out") -> Out | AI20: =if(C20>0,"In","Out") -> Out
A21: 27/08/26 | B21: Metapay | C21: -9.71 | D21: Sent | E21: Mercury Credit | F21: METAPAY*MV4B | I21: 9691 | J21: Ivan Amelong | K21: FinancialInstitutionsAndFees | P21: ############ | Q21: MXN | T21: i@nexiu.ai | X21: 2026 | Y21: 2026 | Z21: 8 | AA21: 8 | AB21: 3 | AC21: =VLOOKUP($B21,Dictionary_v2!$B:$E,2,0) -> P&L | AD21: Recurring | AE21: =VLOOKUP($B21,Dictionary_v2!$B:$E,3,0) -> 3. Platform | AF21: =VLOOKUP(AE21,Dictionary_v2!R:S,2,0) -> 3. Platform | AG21: =VLOOKUP($B21,Dictionary_v2!$B:$E,4,0) -> 2. Fixed | AH21: =if(C21>0,"In","Out") -> Out | AI21: =if(C21>0,"In","Out") -> Out
A22: 27/08/26 | B22: Intl. Transaction Fee | C22: -0.29 | D22: Sent | E22: Mercury Credit | K22: FinancialInstitutionsAndFees | P22: ############ | X22: 2026 | Y22: 2026 | Z22: 8 | AA22: 8 | AB22: 3 | AC22: =VLOOKUP($B22,Dictionary_v2!$B:$E,2,0) -> P&L | AD22: Recurring | AE22: =VLOOKUP($B22,Dictionary_v2!$B:$E,3,0) -> 3. Platform | AF22: =VLOOKUP(AE22,Dictionary_v2!R:S,2,0) -> 3. Platform | AG22: =VLOOKUP($B22,Dictionary_v2!$B:$E,4,0) -> 2. Fixed | AH22: =if(C22>0,"In","Out") -> Out | AI22: =if(C22>0,"In","Out") -> Out
A23: 27/08/26 | B23: Facebook | C23: -498.48 | D23: Failed | E23: Mercury Credit | F23: FACEBK *X56MV3EAR4 | I23: 3684 | J23: Ivan Amelong | K23: Advertising | P23: ############ | Q23: USD | T23: i@nexiu.ai | V23: This transaction failed because it exceeded the spend limit for the card. | X23: 2026 | Y23: 2026 | Z23: 8 | AA23: 8 | AB23: 3 | AC23: =VLOOKUP($B23,Dictionary_v2!$B:$E,2,0) -> P&L | AD23: Recurring | AE23: =VLOOKUP($B23,Dictionary_v2!$B:$E,3,0) -> 2. Candidates Sourcing | AF23: =VLOOKUP(AE23,Dictionary_v2!R:S,2,0) -> 2. Candidates Sourcing | AG23: =VLOOKUP($B23,Dictionary_v2!$B:$E,4,0) -> 1. Social media | AH23: =if(C23>0,"In","Out") -> Out | AI23: =if(C23>0,"In","Out") -> Out
A24: 27/08/26 | B24: Facebook | C24: -744 | D24: Failed | E24: Mercury Credit | F24: FACEBK *SHMYV5JAR4 | I24: 3684 | J24: Ivan Amelong | K24: Advertising | P24: ############ | Q24: USD | T24: i@nexiu.ai | V24: This transaction failed because it exceeded the spend limit for the card. | X24: 2026 | Y24: 2026 | Z24: 8 | AA24: 8 | AB24: 3 | AC24: =VLOOKUP($B24,Dictionary_v2!$B:$E,2,0) -> P&L | AD24: Recurring | AE24: =VLOOKUP($B24,Dictionary_v2!$B:$E,3,0) -> 2. Candidates Sourcing | AF24: =VLOOKUP(AE24,Dictionary_v2!R:S,2,0) -> 2. Candidates Sourcing | AG24: =VLOOKUP($B24,Dictionary_v2!$B:$E,4,0) -> 1. Social media | AH24: =if(C24>0,"In","Out") -> Out | AI24: =if(C24>0,"In","Out") -> Out
A25: 27/08/26 | B25: Facebook | C25: -744 | D25: Failed | E25: Mercury Credit | F25: FACEBK *VDZRH46AR4 | I25: 3684 | J25: Ivan Amelong | K25: Advertising | P25: ############ | Q25: USD | T25: i@nexiu.ai | V25: This transaction failed because it exceeded the spend limit for the card. | X25: 2026 | Y25: 2026 | Z25: 8 | AA25: 8 | AB25: 3 | AC25: =VLOOKUP($B25,Dictionary_v2!$B:$E,2,0) -> P&L | AD25: Recurring | AE25: =VLOOKUP($B25,Dictionary_v2!$B:$E,3,0) -> 2. Candidates Sourcing | AF25: =VLOOKUP(AE25,Dictionary_v2!R:S,2,0) -> 2. Candidates Sourcing | AG25: =VLOOKUP($B25,Dictionary_v2!$B:$E,4,0) -> 1. Social media | AH25: =if(C25>0,"In","Out") -> Out | AI25: =if(C25>0,"In","Out") -> Out
A26: 27/08/26 | B26: Facebook | C26: 0 | D26: Failed | E26: Mercury Credit | F26: FACEBK *YK7JP32AR4 | I26: 3684 | J26: Ivan Amelong | K26: Advertising | P26: ############ | Q26: USD | T26: i@nexiu.ai | V26: The merchant canceled this transaction, possibly due to incorrect billing information. | X26: 2026 | Y26: 2026 | Z26: 8 | AA26: 8 | AB26: 3 | AC26: =VLOOKUP($B26,Dictionary_v2!$B:$E,2,0) -> P&L | AD26: Recurring | AE26: =VLOOKUP($B26,Dictionary_v2!$B:$E,3,0) -> 2. Candidates Sourcing | AF26: =VLOOKUP(AE26,Dictionary_v2!R:S,2,0) -> 2. Candidates Sourcing | AG26: =VLOOKUP($B26,Dictionary_v2!$B:$E,4,0) -> 1. Social media | AH26: =if(C26>0,"In","Out") -> Out | AI26: =if(C26>0,"In","Out") -> Out
A27: 26/08/26 | B27: Facebook | C27: -498.48 | D27: Failed | E27: Mercury Credit | F27: FACEBK *X7Z9P32AR4 | I27: 3684 | J27: Ivan Amelong | K27: Advertising | P27: ############ | Q27: USD | T27: i@nexiu.ai | V27: This transaction failed because it exceeded the spend limit for the card. | X27: 2026 | Y27: 2026 | Z27: 8 | AA27: 8 | AB27: 3 | AC27: =VLOOKUP($B27,Dictionary_v2!$B:$E,2,0) -> P&L | AD27: Recurring | AE27: =VLOOKUP($B27,Dictionary_v2!$B:$E,3,0) -> 2. Candidates Sourcing | AF27: =VLOOKUP(AE27,Dictionary_v2!R:S,2,0) -> 2. Candidates Sourcing | AG27: =VLOOKUP($B27,Dictionary_v2!$B:$E,4,0) -> 1. Social media | AH27: =if(C27>0,"In","Out") -> Out | AI27: =if(C27>0,"In","Out") -> Out
A28: 26/08/26 | B28: Facebook | C28: -744 | D28: Failed | E28: Mercury Credit | F28: FACEBK *4AK8Q3NAR4 | I28: 3684 | J28: Ivan Amelong | K28: Advertising | P28: ############ | Q28: USD | T28: i@nexiu.ai | V28: This transaction failed because it exceeded the spend limit for the card. | X28: 2026 | Y28: 2026 | Z28: 8 | AA28: 8 | AB28: 3 | AC28: =VLOOKUP($B28,Dictionary_v2!$B:$E,2,0) -> P&L | AD28: Recurring | AE28: =VLOOKUP($B28,Dictionary_v2!$B:$E,3,0) -> 2. Candidates Sourcing | AF28: =VLOOKUP(AE28,Dictionary_v2!R:S,2,0) -> 2. Candidates Sourcing | AG28: =VLOOKUP($B28,Dictionary_v2!$B:$E,4,0) -> 1. Social media | AH28: =if(C28>0,"In","Out") -> Out | AI28: =if(C28>0,"In","Out") -> Out
A29: 26/08/26 | B29: Facebook | C29: -744 | D29: Failed | E29: Mercury Credit | F29: FACEBK *HEU5852BR4 | I29: 3684 | J29: Ivan Amelong | K29: Advertising | P29: ############ | Q29: USD | T29: i@nexiu.ai | V29: This transaction failed because it exceeded the spend limit for the card. | X29: 2026 | Y29: 2026 | Z29: 8 | AA29: 8 | AB29: 3 | AC29: =VLOOKUP($B29,Dictionary_v2!$B:$E,2,0) -> P&L | AD29: Recurring | AE29: =VLOOKUP($B29,Dictionary_v2!$B:$E,3,0) -> 2. Candidates Sourcing | AF29: =VLOOKUP(AE29,Dictionary_v2!R:S,2,0) -> 2. Candidates Sourcing | AG29: =VLOOKUP($B29,Dictionary_v2!$B:$E,4,0) -> 1. Social media | AH29: =if(C29>0,"In","Out") -> Out | AI29: =if(C29>0,"In","Out") -> Out
A30: 26/08/26 | B30: Facebook | C30: -744 | D30: Failed | E30: Mercury Credit | F30: FACEBK *C55BP5AAR4 | I30: 3684 | J30: Ivan Amelong | K30: Advertising | P30: ############ | Q30: USD | T30: i@nexiu.ai | V30: This transaction failed because it exceeded the spend limit for the card. | X30: 2026 | Y30: 2026 | Z30: 8 | AA30: 8 | AB30: 3 | AC30: =VLOOKUP($B30,Dictionary_v2!$B:$E,2,0) -> P&L | AD30: Recurring | AE30: =VLOOKUP($B30,Dictionary_v2!$B:$E,3,0) -> 2. Candidates Sourcing | AF30: =VLOOKUP(AE30,Dictionary_v2!R:S,2,0) -> 2. Candidates Sourcing | AG30: =VLOOKUP($B30,Dictionary_v2!$B:$E,4,0) -> 1. Social media | AH30: =if(C30>0,"In","Out") -> Out | AI30: =if(C30>0,"In","Out") -> Out
A31: 26/08/26 | B31: Facebook | C31: -744 | D31: Failed | E31: Mercury Credit | F31: FACEBK *696634WAR4 | I31: 3684 | J31: Ivan Amelong | K31: Advertising | P31: ############ | Q31: USD | T31: i@nexiu.ai | V31: This transaction failed because it exceeded the spend limit for the card. | X31: 2026 | Y31: 2026 | Z31: 8 | AA31: 8 | AB31: 3 | AC31: =VLOOKUP($B31,Dictionary_v2!$B:$E,2,0) -> P&L | AD31: Recurring | AE31: =VLOOKUP($B31,Dictionary_v2!$B:$E,3,0) -> 2. Candidates Sourcing | AF31: =VLOOKUP(AE31,Dictionary_v2!R:S,2,0) -> 2. Candidates Sourcing | AG31: =VLOOKUP($B31,Dictionary_v2!$B:$E,4,0) -> 1. Social media | AH31: =if(C31>0,"In","Out") -> Out | AI31: =if(C31>0,"In","Out") -> Out
A32: 26/08/26 | B32: Facebook | C32: -498.48 | D32: Failed | E32: Mercury Credit | F32: FACEBK *2UU9P32AR4 | I32: 3684 | J32: Ivan Amelong | K32: Advertising | P32: ############ | Q32: USD | T32: i@nexiu.ai | V32: This transaction failed because it exceeded the spend limit for the card. | X32: 2026 | Y32: 2026 | Z32: 8 | AA32: 8 | AB32: 3 | AC32: =VLOOKUP($B32,Dictionary_v2!$B:$E,2,0) -> P&L | AD32: Recurring | AE32: =VLOOKUP($B32,Dictionary_v2!$B:$E,3,0) -> 2. Candidates Sourcing | AF32: =VLOOKUP(AE32,Dictionary_v2!R:S,2,0) -> 2. Candidates Sourcing | AG32: =VLOOKUP($B32,Dictionary_v2!$B:$E,4,0) -> 1. Social media | AH32: =if(C32>0,"In","Out") -> Out | AI32: =if(C32>0,"In","Out") -> Out
A33: 26/08/26 | B33: Facebook | C33: -744 | D33: Failed | E33: Mercury Credit | F33: FACEBK *2G3QV5JAR4 | I33: 3684 | J33: Ivan Amelong | K33: Advertising | P33: ############ | Q33: USD | T33: i@nexiu.ai | V33: This transaction failed because it exceeded the spend limit for the card. | X33: 2026 | Y33: 2026 | Z33: 8 | AA33: 8 | AB33: 3 | AC33: =VLOOKUP($B33,Dictionary_v2!$B:$E,2,0) -> P&L | AD33: Recurring | AE33: =VLOOKUP($B33,Dictionary_v2!$B:$E,3,0) -> 2. Candidates Sourcing | AF33: =VLOOKUP(AE33,Dictionary_v2!R:S,2,0) -> 2. Candidates Sourcing | AG33: =VLOOKUP($B33,Dictionary_v2!$B:$E,4,0) -> 1. Social media | AH33: =if(C33>0,"In","Out") -> Out | AI33: =if(C33>0,"In","Out") -> Out
A34: 26/08/26 | B34: Facebook | C34: -498.48 | D34: Failed | E34: Mercury Credit | F34: FACEBK *4UQ9P32AR4 | I34: 3684 | J34: Ivan Amelong | K34: Advertising | P34: ############ | Q34: USD | T34: i@nexiu.ai | V34: This transaction failed because it exceeded the spend limit for the card. | X34: 2026 | Y34: 2026 | Z34: 8 | AA34: 8 | AB34: 3 | AC34: =VLOOKUP($B34,Dictionary_v2!$B:$E,2,0) -> P&L | AD34: Recurring | AE34: =VLOOKUP($B34,Dictionary_v2!$B:$E,3,0) -> 2. Candidates Sourcing | AF34: =VLOOKUP(AE34,Dictionary_v2!R:S,2,0) -> 2. Candidates Sourcing | AG34: =VLOOKUP($B34,Dictionary_v2!$B:$E,4,0) -> 1. Social media | AH34: =if(C34>0,"In","Out") -> Out | AI34: =if(C34>0,"In","Out") -> Out
A35: 26/08/26 | B35: Facebook | C35: -744 | D35: Failed | E35: Mercury Credit | F35: FACEBK *XLQ9P32AR4 | I35: 3684 | J35: Ivan Amelong | K35: Advertising | P35: ############ | Q35: USD | T35: i@nexiu.ai | V35: This transaction failed because it exceeded the spend limit for the card. | X35: 2026 | Y35: 2026 | Z35: 8 | AA35: 8 | AB35: 3 | AC35: =VLOOKUP($B35,Dictionary_v2!$B:$E,2,0) -> P&L | AD35: Recurring | AE35: =VLOOKUP($B35,Dictionary_v2!$B:$E,3,0) -> 2. Candidates Sourcing | AF35: =VLOOKUP(AE35,Dictionary_v2!R:S,2,0) -> 2. Candidates Sourcing | AG35: =VLOOKUP($B35,Dictionary_v2!$B:$E,4,0) -> 1. Social media | AH35: =if(C35>0,"In","Out") -> Out | AI35: =if(C35>0,"In","Out") -> Out
A36: 26/08/26 | B36: Welcome to Column N.A. (Mercury Checking xx5998) | C36: -5000 | D36: Sent | E36: Treasury | F36: Liquidation of Treasury assets | P36: ############ | U36: 20260826B1Q8152C298051 | X36: 2026 | Y36: 2026 | Z36: 8 | AA36: 8 | AB36: 3 | AC36: =VLOOKUP($B36,Dictionary_v2!$B:$E,2,0) -> Intercompany | AD36: Recurring | AE36: =VLOOKUP($B36,Dictionary_v2!$B:$E,3,0) | AG36: =VLOOKUP($B36,Dictionary_v2!$B:$E,4,0) | AH36: =if(C36>0,"In","Out") -> Out | AI36: =if(C36>0,"In","Out") -> Out
A37: 26/08/26 | B37: Treasury | C37: 5000 | D37: Sent | E37: Welcome to Column N.A. (Mercury Checking xx5998) | F37: Liquidation of Treasury assets | P37: ############ | U37: 20260826B1Q8152C298051 | X37: 2026 | Y37: 2026 | Z37: 8 | AA37: 8 | AB37: 3 | AC37: =VLOOKUP($B37,Dictionary_v2!$B:$E,2,0) -> Intercompany | AD37: Recurring | AE37: =VLOOKUP($B37,Dictionary_v2!$B:$E,3,0) | AG37: =VLOOKUP($B37,Dictionary_v2!$B:$E,4,0) | AH37: =if(C37>0,"In","Out") -> In | AI37: =if(C37>0,"In","Out") -> In
A38: 26/08/26 | B38: Monica Tonanzin García Vega (Monica Tonanzin García Vega) | C38: -1033 | D38: Sent | E38: Welcome to Column N.A. (Mercury Checking xx5998) | F38: Send Money transaction initiated on Mercury | G38: Contractor, Aug 2026 | P38: ############ | U38: 121145431600187 | X38: 2026 | Y38: 2026 | Z38: 8 | AA38: 8 | AB38: 3 | AC38: =VLOOKUP($B38,Dictionary_v2!$B:$E,2,0) -> P&L | AD38: Recurring | AE38: =VLOOKUP($B38,Dictionary_v2!$B:$E,3,0) -> 4. People | AF38: =VLOOKUP(AE38,Dictionary_v2!R:S,2,0) -> 4. People | AG38: =VLOOKUP($B38,Dictionary_v2!$B:$E,4,0) -> 1. Operations | AH38: =if(C38>0,"In","Out") -> Out | AI38: =if(C38>0,"In","Out") -> Out
A39: 26/08/26 | B39: Bullmetrix LLC (Bullmetrix LLC) | C39: -1500 | D39: Sent | E39: Welcome to Column N.A. (Mercury Checking xx5998) | F39: Send Money transaction initiated on Mercury | G39: Payment, invoice: 2026485 | P39: ############ | U39: 121145431600179 | X39: 2026 | Y39: 2026 | Z39: 8 | AA39: 8 | AB39: 3 | AC39: =VLOOKUP($B39,Dictionary_v2!$B:$E,2,0) -> P&L | AD39: Recurring | AE39: =VLOOKUP($B39,Dictionary_v2!$B:$E,3,0) -> 5. Marketing | AF39: =VLOOKUP(AE39,Dictionary_v2!R:S,2,0) -> 5. Marketing | AG39: =VLOOKUP($B39,Dictionary_v2!$B:$E,4,0) -> 2. Agency | AH39: =if(C39>0,"In","Out") -> Out | AI39: =if(C39>0,"In","Out") -> Out
A40: 26/08/26 | B40: Intl. Wire Foreign Exchange Fee | C40: -10.33 | D40: Sent | E40: Welcome to Column N.A. (Mercury Checking xx5998) | F40: Currency exchange fee for international wire | P40: ############ | X40: 2026 | Y40: 2026 | Z40: 8 | AA40: 8 | AB40: 3 | AC40: =VLOOKUP($B40,Dictionary_v2!$B:$E,2,0) -> P&L | AD40: Recurring | AE40: =VLOOKUP($B40,Dictionary_v2!$B:$E,3,0) -> 3. Platform | AF40: =VLOOKUP(AE40,Dictionary_v2!R:S,2,0) -> 3. Platform | AG40: =VLOOKUP($B40,Dictionary_v2!$B:$E,4,0) -> 2. Fixed | AH40: =if(C40>0,"In","Out") -> Out | AI40: =if(C40>0,"In","Out") -> Out
A41: 26/08/26 | B41: Andrea Gomez (Andrea Gómez Romero) | C41: -1032.96 | D41: Sent | E41: Welcome to Column N.A. (Mercury Checking xx5998) | F41: Send Money transaction initiated on Mercury | G41: From Nexiu AI LLC | P41: ############ | X41: 2026 | Y41: 2026 | Z41: 8 | AA41: 8 | AB41: 3 | AC41: =VLOOKUP($B41,Dictionary_v2!$B:$E,2,0) -> P&L | AD41: Recurring | AE41: =VLOOKUP($B41,Dictionary_v2!$B:$E,3,0) -> 4. People | AF41: =VLOOKUP(AE41,Dictionary_v2!R:S,2,0) -> 4. People | AG41: =VLOOKUP($B41,Dictionary_v2!$B:$E,4,0) -> 1. Operations | AH41: =if(C41>0,"In","Out") -> Out | AI41: =if(C41>0,"In","Out") -> Out
...

Sheet Ajustes Manuales cada mes
B2: 1 | C2: Facebook, card 2354 ---> | D2: 3. Platform | E2: 3. Platform | F2: 3. Messaging
B3: 2 | C3: Anthropic, 200 USD | D3: 6. Tech salaries | E3: 6. Other fixed and admin | F3: 1. Salaries

Sheet DolarApp
A1: created_on | B1: transaction_type | C1: transaction_state | D1: name | E1: description | F1: local_amount | G1: local_currency | H1: fx_rate | I1: base_amount | J1: base_currency | K1: fee_amount | L1: fee_currency | M1: adjustment_amount | N1: adjustment_currency | O1: post_transaction_balance | P1: card_last_four | Q1: cardholder_name | R1: merchant_category | S1: completed_at | T1: Year | U1: Month | V1: Quarter | W1: Statement | X1: Type 1 | Y1: Type 2 | Z1: Type 2_B | AA1: Type 3 | AB1: Type 4 | AC1: Status
A2: 46262.959 | B2: WITHDRAW | C2: COMPLETED | D2: Ivan Amelong | E2: Agosto 2026 | F2: -14311.45 | G2: MXN | H2: 17.0196 | I2: -840.88 | J2: USDC | K2: 0 | L2: USDC | M2: 0 | N2: USDC | O2: 869.14 | P2: XXXX | Q2: XXXX | R2: XXXX | S2: 46262.959 | T2: =YEAR(A2) -> 2026 | U2: =MONTH(A2) -> 8 | V2: =VLOOKUP(U2,Dictionary_v2!$O$3:$P$15,2,0) -> 3 | W2: =VLOOKUP($D2,Dictionary_v2!$G:$J,2,0) -> P&L | X2: Recurring | Y2: =VLOOKUP($D2,Dictionary_v2!$G:$J,3,0) -> 7. Founders | Z2: =VLOOKUP(Y2,Dictionary_v2!R:S,2,0) -> 6. Other fixed and admin | AA2: =VLOOKUP($D2,Dictionary_v2!$G:$J,4,0) -> 1. Salaries | AB2: =if(F2>0,"In","Out") -> Out | AC2: =VLOOKUP(C2,Dictionary_v2!L:M,2,0) -> Sent
A3: 46262.959 | B3: WITHDRAW | C3: COMPLETED | D3: Federico David Naides | E3: Agosto 2026 | F3: -14311.45 | G3: MXN | H3: 17.0196 | I3: -840.88 | J3: USDC | K3: 0 | L3: USDC | M3: 0 | N3: USDC | O3: 1710.02 | P3: XXXX | Q3: XXXX | R3: XXXX | S3: 46262.959 | T3: =YEAR(A3) -> 2026 | U3: =MONTH(A3) -> 8 | V3: =VLOOKUP(U3,Dictionary_v2!$O$3:$P$15,2,0) -> 3 | W3: =VLOOKUP($D3,Dictionary_v2!$G:$J,2,0) -> P&L | X3: Recurring | Y3: =VLOOKUP($D3,Dictionary_v2!$G:$J,3,0) -> 7. Founders | Z3: =VLOOKUP(Y3,Dictionary_v2!R:S,2,0) -> 6. Other fixed and admin | AA3: =VLOOKUP($D3,Dictionary_v2!$G:$J,4,0) -> 1. Salaries | AB3: =if(F3>0,"In","Out") -> Out | AC3: =VLOOKUP(C3,Dictionary_v2!L:M,2,0) -> Sent
A4: 46261.695 | B4: CARD_PAYMENT | C4: COMPLETED | D4: Www.mirlo.mx Mexico | E4: WWW.MIRLO.MX | F4: -40.81 | G4: MXN | H4: 16.9656 | I4: -2.41 | J4: USDC | K4: 0 | L4: USDC | M4: 0 | N4: USDC | O4: 869.14 | P4: 2535 | Q4: Ivan Amelong | R4: SERVICES | S4: 46263.375 | T4: =YEAR(A4) -> 2026 | U4: =MONTH(A4) -> 8 | V4: =VLOOKUP(U4,Dictionary_v2!$O$3:$P$15,2,0) -> 3 | W4: =VLOOKUP($D4,Dictionary_v2!$G:$J,2,0) -> P&L | X4: Recurring | Y4: =VLOOKUP($D4,Dictionary_v2!$G:$J,3,0) -> 3. Platform | Z4: =VLOOKUP(Y4,Dictionary_v2!R:S,2,0) -> 3. Platform | AA4: =VLOOKUP($D4,Dictionary_v2!$G:$J,4,0) -> 1. Variable | AB4: =if(F4>0,"In","Out") -> Out | AC4: =VLOOKUP(C4,Dictionary_v2!L:M,2,0) -> Sent
A5: 46255.95 | B5: WITHDRAW | C5: COMPLETED | D5: Nadia Meline Karaguezian | E5: Impuestos Jul 26 | F5: -4171 | G5: MXN | H5: 16.9059 | I5: -246.72 | J5: USDC | K5: 0 | L5: USDC | M5: 0 | N5: USDC | O5: 2553.31 | P5: XXXX | Q5: XXXX | R5: XXXX | S5: 46255.95 | T5: =YEAR(A5) -> 2026 | U5: =MONTH(A5) -> 8 | V5: =VLOOKUP(U5,Dictionary_v2!$O$3:$P$15,2,0) -> 3 | W5: =VLOOKUP($D5,Dictionary_v2!$G:$J,2,0) -> P&L | X5: Recurring | Y5: =VLOOKUP($D5,Dictionary_v2!$G:$J,3,0) -> 8. Other fixed costs | Z5: =VLOOKUP(Y5,Dictionary_v2!R:S,2,0) -> 6. Other fixed and admin | AA5: =VLOOKUP($D5,Dictionary_v2!$G:$J,4,0) -> 4. Taxes | AB5: =if(F5>0,"In","Out") -> Out | AC5: =VLOOKUP(C5,Dictionary_v2!L:M,2,0) -> Sent
A6: 46255.799 | B6: DEPOSIT | C6: COMPLETED | D6: KEKO MOBILITY SA DE CV | E6: Pago Reclutamiento Nexiu 371 DyA ML | F6: 30160 | G6: MXN | H6: 16.9282 | I6: 1781.64 | J6: USDC | K6: 0 | L6: USDC | M6: 0 | N6: USDC | O6: 2800.03 | P6: XXXX | Q6: XXXX | R6: XXXX | S6: 46255.799 | T6: =YEAR(A6) -> 2026 | U6: =MONTH(A6) -> 8 | V6: =VLOOKUP(U6,Dictionary_v2!$O$3:$P$15,2,0) -> 3 | W6: =VLOOKUP($D6,Dictionary_v2!$G:$J,2,0) -> P&L | X6: Recurring | Y6: =VLOOKUP($D6,Dictionary_v2!$G:$J,3,0) -> 1. Collections | Z6: =VLOOKUP(Y6,Dictionary_v2!R:S,2,0) -> 1. Collections | AA6: =VLOOKUP($D6,Dictionary_v2!$G:$J,4,0) -> 1. Full Stack | AB6: =if(F6>0,"In","Out") -> In | AC6: =VLOOKUP(C6,Dictionary_v2!L:M,2,0) -> Sent
A7: 46253.731 | B7: WITHDRAW | C7: COMPLETED | D7: Gloria L Guzman M | F7: -1741.5 | G7: MXN | H7: 16.9668 | I7: -102.64 | J7: USDC | K7: 0 | L7: USDC | M7: 0 | N7: USDC | O7: 1018.38 | P7: XXXX | Q7: XXXX | R7: XXXX | S7: 46253.731 | T7: =YEAR(A7) -> 2026 | U7: =MONTH(A7) -> 8 | V7: =VLOOKUP(U7,Dictionary_v2!$O$3:$P$15,2,0) -> 3 | W7: =VLOOKUP($D7,Dictionary_v2!$G:$J,2,0) -> P&L | X7: Recurring | Y7: =VLOOKUP($D7,Dictionary_v2!$G:$J,3,0) -> 1. Collections | Z7: =VLOOKUP(Y7,Dictionary_v2!R:S,2,0) -> 1. Collections | AA7: =VLOOKUP($D7,Dictionary_v2!$G:$J,4,0) -> 2. SaaS | AB7: =if(F7>0,"In","Out") -> Out | AC7: =VLOOKUP(C7,Dictionary_v2!L:M,2,0) -> Sent
A8: 46253.647 | B8: CARD_PAYMENT | C8: COMPLETED | D8: Www.mirlo.mx Mexico | E8: WWW.MIRLO.MX | F8: -74.1 | G8: MXN | H8: 16.9666 | I8: -4.37 | J8: USDC | K8: 0 | L8: USDC | M8: 0 | N8: USDC | O8: 1018.38 | P8: 2535 | Q8: Ivan Amelong | R8: SERVICES | S8: 46255.375 | T8: =YEAR(A8) -> 2026 | U8: =MONTH(A8) -> 8 | V8: =VLOOKUP(U8,Dictionary_v2!$O$3:$P$15,2,0) -> 3 | W8: =VLOOKUP($D8,Dictionary_v2!$G:$J,2,0) -> P&L | X8: Recurring | Y8: =VLOOKUP($D8,Dictionary_v2!$G:$J,3,0) -> 3. Platform | Z8: =VLOOKUP(Y8,Dictionary_v2!R:S,2,0) -> 3. Platform | AA8: =VLOOKUP($D8,Dictionary_v2!$G:$J,4,0) -> 1. Variable | AB8: =if(F8>0,"In","Out") -> Out | AC8: =VLOOKUP(C8,Dictionary_v2!L:M,2,0) -> Sent
A9: 46252.98 | B9: CARD_PAYMENT | C9: COMPLETED | D9: Www.mirlo.mx Mexico | E9: WWW.MIRLO.MX | F9: -78.26 | G9: MXN | H9: 17.0638 | I9: -4.59 | J9: USDC | K9: 0 | L9: USDC | M9: 0 | N9: USDC | O9: 1018.38 | P9: 2535 | Q9: Ivan Amelong | R9: SERVICES | S9: 46254.375 | T9: =YEAR(A9) -> 2026 | U9: =MONTH(A9) -> 8 | V9: =VLOOKUP(U9,Dictionary_v2!$O$3:$P$15,2,0) -> 3 | W9: =VLOOKUP($D9,Dictionary_v2!$G:$J,2,0) -> P&L | X9: Recurring | Y9: =VLOOKUP($D9,Dictionary_v2!$G:$J,3,0) -> 3. Platform | Z9: =VLOOKUP(Y9,Dictionary_v2!R:S,2,0) -> 3. Platform | AA9: =VLOOKUP($D9,Dictionary_v2!$G:$J,4,0) -> 1. Variable | AB9: =if(F9>0,"In","Out") -> Out | AC9: =VLOOKUP(C9,Dictionary_v2!L:M,2,0) -> Sent
A10: 46247.897 | B10: WITHDRAW | C10: COMPLETED | D10: Gloria L Guzman M | E10: Material Congreso AMESP | F10: -1741.5 | G10: MXN | H10: 17.0207 | I10: -102.32 | J10: USDC | K10: 0 | L10: USDC | M10: 0 | N10: USDC | O10: 1129.98 | P10: XXXX | Q10: XXXX | R10: XXXX | S10: 46247.897 | T10: =YEAR(A10) -> 2026 | U10: =MONTH(A10) -> 8 | V10: =VLOOKUP(U10,Dictionary_v2!$O$3:$P$15,2,0) -> 3 | W10: =VLOOKUP($D10,Dictionary_v2!$G:$J,2,0) -> P&L | X10: Recurring | Y10: =VLOOKUP($D10,Dictionary_v2!$G:$J,3,0) -> 1. Collections | Z10: =VLOOKUP(Y10,Dictionary_v2!R:S,2,0) -> 1. Collections | AA10: =VLOOKUP($D10,Dictionary_v2!$G:$J,4,0) -> 2. SaaS | AB10: =if(F10>0,"In","Out") -> Out | AC10: =VLOOKUP(C10,Dictionary_v2!L:M,2,0) -> Sent
A11: 46245.798 | B11: WITHDRAW | C11: COMPLETED | D11: AMESP Asociacion Mexicana de Empresas de Seguridad Privada | E11: 2do-congreso-seguridad-nexiu | F11: -25000 | G11: MXN | H11: 17.086 | I11: -1463.18 | J11: USDC | K11: 0 | L11: USDC | M11: 0 | N11: USDC | O11: 1232.3 | P11: XXXX | Q11: XXXX | R11: XXXX | S11: 46245.798 | T11: =YEAR(A11) -> 2026 | U11: =MONTH(A11) -> 8 | V11: =VLOOKUP(U11,Dictionary_v2!$O$3:$P$15,2,0) -> 3 | W11: =VLOOKUP($D11,Dictionary_v2!$G:$J,2,0) -> P&L | X11: Recurring | Y11: =VLOOKUP($D11,Dictionary_v2!$G:$J,3,0) -> 5. Marketing | Z11: =VLOOKUP(Y11,Dictionary_v2!R:S,2,0) -> 5. Marketing | AA11: =VLOOKUP($D11,Dictionary_v2!$G:$J,4,0) -> 3. Events | AB11: =if(F11>0,"In","Out") -> Out | AC11: =VLOOKUP(C11,Dictionary_v2!L:M,2,0) -> Sent
A12: 46245.542 | B12: DEPOSIT | C12: COMPLETED | D12: NEXIU AI LLC | E12: PAYMENT NEXIU AI LLC MRCR-QZ09MPAY7F [LatAm Talent & Recruit] From Nexiu AI, LLC via mercury.com | F12: 2000 | G12: USD | H12: 1 | I12: 2000 | J12: USDC | K12: 0 | L12: USDC | M12: 0 | N12: USDC | O12: 2695.48 | P12: XXXX | Q12: XXXX | R12: XXXX | S12: 46245.542 | T12: =YEAR(A12) -> 2026 | U12: =MONTH(A12) -> 8 | V12: =VLOOKUP(U12,Dictionary_v2!$O$3:$P$15,2,0) -> 3 | W12: =VLOOKUP($D12,Dictionary_v2!$G:$J,2,0) -> BS | X12: Recurring | Y12: =VLOOKUP($D12,Dictionary_v2!$G:$J,3,0) -> 0. Investments | Z12: =VLOOKUP(Y12,Dictionary_v2!R:S,2,0) -> 0. Investments | AA12: =VLOOKUP($D12,Dictionary_v2!$G:$J,4,0) -> 4. Intercompany | AB12: =if(F12>0,"In","Out") -> In | AC12: =VLOOKUP(C12,Dictionary_v2!L:M,2,0) -> Sent
A13: 46244.866 | B13: CARD_PAYMENT | C13: COMPLETED | D13: Viva Aerobus Apo | E13: Viva Aerobus | F13: -5771.81 | G13: MXN | H13: 17.1385 | I13: -336.78 | J13: USDC | K13: 0 | L13: USDC | M13: 0 | N13: USDC | O13: 1232.3 | P13: 2535 | Q13: Ivan Amelong | R13: TRAVEL | S13: 46246.375 | T13: =YEAR(A13) -> 2026 | U13: =MONTH(A13) -> 8 | V13: =VLOOKUP(U13,Dictionary_v2!$O$3:$P$15,2,0) -> 3 | W13: =VLOOKUP($D13,Dictionary_v2!$G:$J,2,0) -> P&L | X13: Recurring | Y13: =VLOOKUP($D13,Dictionary_v2!$G:$J,3,0) -> 5. Marketing | Z13: =VLOOKUP(Y13,Dictionary_v2!R:S,2,0) -> 5. Marketing | AA13: =VLOOKUP($D13,Dictionary_v2!$G:$J,4,0) -> 3. Events | AB13: =if(F13>0,"In","Out") -> Out | AC13: =VLOOKUP(C13,Dictionary_v2!L:M,2,0) -> Sent
A14: 46244.664 | B14: CARD_PAYMENT | C14: COMPLETED | D14: Www.mirlo.mx Mexico | E14: WWW.MIRLO.MX | F14: -111.55 | G14: MXN | H14: 17.1368 | I14: -6.51 | J14: USDC | K14: 0 | L14: USDC | M14: 0 | N14: USDC | O14: 1232.3 | P14: 2535 | Q14: Ivan Amelong | R14: SERVICES | S14: 46246.375 | T14: =YEAR(A14) -> 2026 | U14: =MONTH(A14) -> 8 | V14: =VLOOKUP(U14,Dictionary_v2!$O$3:$P$15,2,0) -> 3 | W14: =VLOOKUP($D14,Dictionary_v2!$G:$J,2,0) -> P&L | X14: Recurring | Y14: =VLOOKUP($D14,Dictionary_v2!$G:$J,3,0) -> 3. Platform | Z14: =VLOOKUP(Y14,Dictionary_v2!R:S,2,0) -> 3. Platform | AA14: =VLOOKUP($D14,Dictionary_v2!$G:$J,4,0) -> 1. Variable | AB14: =if(F14>0,"In","Out") -> Out | AC14: =VLOOKUP(C14,Dictionary_v2!L:M,2,0) -> Sent
A15: 46242.024 | B15: CARD_PAYMENT | C15: COMPLETED | D15: Www.mirlo.mx Mexico | E15: WWW.MIRLO.MX | F15: -119.87 | G15: MXN | H15: 17.1212 | I15: -7 | J15: USDC | K15: 0 | L15: USDC | M15: 0 | N15: USDC | O15: 1038.77 | P15: 2535 | Q15: Ivan Amelong | R15: SERVICES | S15: 46243.375 | T15: =YEAR(A15) -> 2026 | U15: =MONTH(A15) -> 8 | V15: =VLOOKUP(U15,Dictionary_v2!$O$3:$P$15,2,0) -> 3 | W15: =VLOOKUP($D15,Dictionary_v2!$G:$J,2,0) -> P&L | X15: Recurring | Y15: =VLOOKUP($D15,Dictionary_v2!$G:$J,3,0) -> 3. Platform | Z15: =VLOOKUP(Y15,Dictionary_v2!R:S,2,0) -> 3. Platform | AA15: =VLOOKUP($D15,Dictionary_v2!$G:$J,4,0) -> 1. Variable | AB15: =if(F15>0,"In","Out") -> Out | AC15: =VLOOKUP(C15,Dictionary_v2!L:M,2,0) -> Sent
A16: 46241.993 | B16: DEPOSIT | C16: COMPLETED | D16: AZUCENA DANAE MORALES MARTINEZ | E16: Pago LaTam Talent and Recruitment | F16: 12062 | G16: MXN | H16: 17.1512 | I16: 703.27 | J16: USDC | K16: 0 | L16: USDC | M16: 0 | N16: USDC | O16: 1045.77 | P16: XXXX | Q16: XXXX | R16: XXXX | S16: 46241.993 | T16: =YEAR(A16) -> 2026 | U16: =MONTH(A16) -> 8 | V16: =VLOOKUP(U16,Dictionary_v2!$O$3:$P$15,2,0) -> 3 | W16: =VLOOKUP($D16,Dictionary_v2!$G:$J,2,0) -> P&L | X16: Recurring | Y16: =VLOOKUP($D16,Dictionary_v2!$G:$J,3,0) -> 1. Collections | Z16: =VLOOKUP(Y16,Dictionary_v2!R:S,2,0) -> 1. Collections | AA16: =VLOOKUP($D16,Dictionary_v2!$G:$J,4,0) -> 2. SaaS | AB16: =if(F16>0,"In","Out") -> In | AC16: =VLOOKUP(C16,Dictionary_v2!L:M,2,0) -> Sent
A17: 46241.983 | B17: DEPOSIT | C17: COMPLETED | D17: AZUCENA DANAE MORALES MARTINEZ | E17: Validaci√≥n cuenta LatAm Talent | F17: 1 | G17: MXN | H17: 17.1512 | I17: 0.06 | J17: USDC | K17: 0 | L17: USDC | M17: 0 | N17: USDC | O17: 342.49 | P17: XXXX | Q17: XXXX | R17: XXXX | S17: 46241.983 | T17: =YEAR(A17) -> 2026 | U17: =MONTH(A17) -> 8 | V17: =VLOOKUP(U17,Dictionary_v2!$O$3:$P$15,2,0) -> 3 | W17: =VLOOKUP($D17,Dictionary_v2!$G:$J,2,0) -> P&L | X17: Recurring | Y17: =VLOOKUP($D17,Dictionary_v2!$G:$J,3,0) -> 1. Collections | Z17: =VLOOKUP(Y17,Dictionary_v2!R:S,2,0) -> 1. Collections | AA17: =VLOOKUP($D17,Dictionary_v2!$G:$J,4,0) -> 2. SaaS | AB17: =if(F17>0,"In","Out") -> In | AC17: =VLOOKUP(C17,Dictionary_v2!L:M,2,0) -> Sent
A18: 46240.858 | B18: WITHDRAW | C18: COMPLETED | D18: WeWork Mexico Co S. de R.L. de C.V | E18: Agosto 26 | F18: -10604.72 | G18: MXN | H18: 17.2091 | I18: -616.23 | J18: USDC | K18: 0 | L18: USDC | M18: 0 | N18: USDC | O18: 342.43 | P18: XXXX | Q18: XXXX | R18: XXXX | S18: 46240.858 | T18: =YEAR(A18) -> 2026 | U18: =MONTH(A18) -> 8 | V18: =VLOOKUP(U18,Dictionary_v2!$O$3:$P$15,2,0) -> 3 | W18: =VLOOKUP($D18,Dictionary_v2!$G:$J,2,0) -> P&L | X18: Recurring | Y18: =VLOOKUP($D18,Dictionary_v2!$G:$J,3,0) -> 8. Other fixed costs | Z18: =VLOOKUP(Y18,Dictionary_v2!R:S,2,0) -> 6. Other fixed and admin | AA18: =VLOOKUP($D18,Dictionary_v2!$G:$J,4,0) -> 3. Rent | AB18: =if(F18>0,"In","Out") -> Out | AC18: =VLOOKUP(C18,Dictionary_v2!L:M,2,0) -> Sent
A19: 46240.794 | B19: DEPOSIT | C19: COMPLETED | D19: TECNO AVIV SA DE CV | E19: TECNO AVIV | F19: 4020 | G19: MXN | H19: 17.2077 | I19: 233.62 | J19: USDC | K19: 0 | L19: USDC | M19: 0 | N19: USDC | O19: 958.66 | P19: XXXX | Q19: XXXX | R19: XXXX | S19: 46240.794 | T19: =YEAR(A19) -> 2026 | U19: =MONTH(A19) -> 8 | V19: =VLOOKUP(U19,Dictionary_v2!$O$3:$P$15,2,0) -> 3 | W19: =VLOOKUP($D19,Dictionary_v2!$G:$J,2,0) -> P&L | X19: Recurring | Y19: =VLOOKUP($D19,Dictionary_v2!$G:$J,3,0) -> 1. Collections | Z19: =VLOOKUP(Y19,Dictionary_v2!R:S,2,0) -> 1. Collections | AA19: =VLOOKUP($D19,Dictionary_v2!$G:$J,4,0) -> 2. SaaS | AB19: =if(F19>0,"In","Out") -> In | AC19: =VLOOKUP(C19,Dictionary_v2!L:M,2,0) -> Sent
A20: 46236.436 | B20: CARD_PAYMENT | C20: COMPLETED | D20: Indeed Iei26-02411127 Dublin | E20: Indeed IEI26-02411127 | F20: -769.34 | G20: MXN | H20: 17.3373 | I20: -44.37 | J20: USDC | K20: 0 | L20: USDC | M20: 0 | N20: USDC | O20: 725.05 | P20: 2535 | Q20: Ivan Amelong | R20: SERVICES | S20: 46238.375 | T20: =YEAR(A20) -> 2026 | U20: =MONTH(A20) -> 8 | V20: =VLOOKUP(U20,Dictionary_v2!$O$3:$P$15,2,0) -> 3 | W20: =VLOOKUP($D20,Dictionary_v2!$G:$J,2,0) -> P&L | X20: Recurring | Y20: =VLOOKUP($D20,Dictionary_v2!$G:$J,3,0) -> 2. Candidates Sourcing | Z20: =VLOOKUP(Y20,Dictionary_v2!R:S,2,0) -> 2. Candidates Sourcing | AA20: =VLOOKUP($D20,Dictionary_v2!$G:$J,4,0) -> 2. Job Portals | AB20: =if(F20>0,"In","Out") -> Out | AC20: =VLOOKUP(C20,Dictionary_v2!L:M,2,0) -> Sent
A21: 46235.99 | B21: CARD_PAYMENT | C21: COMPLETED | D21: Www.mirlo.mx Mexico | E21: WWW.MIRLO.MX | F21: -129 | G21: MXN | H21: 17.3373 | I21: -7.44 | J21: USDC | K21: 0 | L21: USDC | M21: 0 | N21: USDC | O21: 725.05 | P21: 2535 | Q21: Ivan Amelong | R21: SERVICES | S21: 46237.375 | T21: =YEAR(A21) -> 2026 | U21: =MONTH(A21) -> 8 | V21: =VLOOKUP(U21,Dictionary_v2!$O$3:$P$15,2,0) -> 3 | W21: =VLOOKUP($D21,Dictionary_v2!$G:$J,2,0) -> P&L | X21: Recurring | Y21: =VLOOKUP($D21,Dictionary_v2!$G:$J,3,0) -> 3. Platform | Z21: =VLOOKUP(Y21,Dictionary_v2!R:S,2,0) -> 3. Platform | AA21: =VLOOKUP($D21,Dictionary_v2!$G:$J,4,0) -> 1. Variable | AB21: =if(F21>0,"In","Out") -> Out | AC21: =VLOOKUP(C21,Dictionary_v2!L:M,2,0) -> Sent
A22: 46235.629 | B22: CARD_PAYMENT | C22: COMPLETED | D22: Payu *google Cloud Miguel Hidalg | E22: Google | F22: -2740.87 | G22: MXN | H22: 17.3373 | I22: -158.09 | J22: USDC | K22: 0 | L22: USDC | M22: 0 | N22: USDC | O22: 725.05 | P22: 2535 | Q22: Ivan Amelong | R22: ENTERTAINMENT | S22: 46238.375 | T22: =YEAR(A22) -> 2026 | U22: =MONTH(A22) -> 8 | V22: =VLOOKUP(U22,Dictionary_v2!$O$3:$P$15,2,0) -> 3 | W22: =VLOOKUP($D22,Dictionary_v2!$G:$J,2,0) -> P&L | X22: Recurring | Y22: =VLOOKUP($D22,Dictionary_v2!$G:$J,3,0) -> 2. Candidates Sourcing | Z22: =VLOOKUP(Y22,Dictionary_v2!R:S,2,0) -> 2. Candidates Sourcing | AA22: =VLOOKUP($D22,Dictionary_v2!$G:$J,4,0) -> 1. Social media | AB22: =if(F22>0,"In","Out") -> Out | AC22: =VLOOKUP(C22,Dictionary_v2!L:M,2,0) -> Sent
A23: 46235.25 | B23: CASHBACK | C23: COMPLETED | D23: Cashback | E23: Cashback payment | F23: 6.44 | G23: USDC | H23: 1 | I23: 6.44 | J23: USDC | K23: 0 | L23: USDC | M23: 0 | N23: USDC | O23: 934.95 | P23: XXXX | Q23: XXXX | R23: XXXX | S23: 46235.25 | T23: =YEAR(A23) -> 2026 | U23: =MONTH(A23) -> 8 | V23: =VLOOKUP(U23,Dictionary_v2!$O$3:$P$15,2,0) -> 3 | W23: =VLOOKUP($D23,Dictionary_v2!$G:$J,2,0) -> P&L | X23: Recurring | Y23: =VLOOKUP($D23,Dictionary_v2!$G:$J,3,0) -> 2. Candidates Sourcing | Z23: =VLOOKUP(Y23,Dictionary_v2!R:S,2,0) -> 2. Candidates Sourcing | AA23: =VLOOKUP($D23,Dictionary_v2!$G:$J,4,0) -> 2. Job Portals | AB23: =if(F23>0,"In","Out") -> In | AC23: =VLOOKUP(C23,Dictionary_v2!L:M,2,0) -> Sent
A24: 46234.715 | B24: WITHDRAW | C24: COMPLETED | D24: Federico David Naides | E24: Servicios Julio 26 | F24: -18214.58 | G24: MXN | H24: 17.3175 | I24: -1051.8 | J24: USDC | K24: 0 | L24: USDC | M24: 0 | N24: USDC | O24: 928.51 | P24: XXXX | Q24: XXXX | R24: XXXX | S24: 46234.715 | T24: =YEAR(A24) -> 2026 | U24: =MONTH(A24) -> 7 | V24: =VLOOKUP(U24,Dictionary_v2!$O$3:$P$15,2,0) -> 3 | W24: =VLOOKUP($D24,Dictionary_v2!$G:$J,2,0) -> P&L | X24: Recurring | Y24: =VLOOKUP($D24,Dictionary_v2!$G:$J,3,0) -> 7. Founders | Z24: =VLOOKUP(Y24,Dictionary_v2!R:S,2,0) -> 6. Other fixed and admin | AA24: =VLOOKUP($D24,Dictionary_v2!$G:$J,4,0) -> 1. Salaries | AB24: =if(F24>0,"In","Out") -> Out | AC24: =VLOOKUP(C24,Dictionary_v2!L:M,2,0) -> Sent
A25: 46232.87 | B25: WITHDRAW | C25: COMPLETED | D25: Ivan Amelong | E25: Julio 26 - Folio 7 | F25: -18214.58 | G25: MXN | H25: 17.4478 | I25: -1043.95 | J25: USDC | K25: 0 | L25: USDC | M25: 0 | N25: USDC | O25: 1980.31 | P25: XXXX | Q25: XXXX | R25: XXXX | S25: 46232.87 | T25: =YEAR(A25) -> 2026 | U25: =MONTH(A25) -> 7 | V25: =VLOOKUP(U25,Dictionary_v2!$O$3:$P$15,2,0) -> 3 | W25: =VLOOKUP($D25,Dictionary_v2!$G:$J,2,0) -> P&L | X25: Recurring | Y25: =VLOOKUP($D25,Dictionary_v2!$G:$J,3,0) -> 7. Founders | Z25: =VLOOKUP(Y25,Dictionary_v2!R:S,2,0) -> 6. Other fixed and admin | AA25: =VLOOKUP($D25,Dictionary_v2!$G:$J,4,0) -> 1. Salaries | AB25: =if(F25>0,"In","Out") -> Out | AC25: =VLOOKUP(C25,Dictionary_v2!L:M,2,0) -> Sent
A26: 46231.871 | B26: DEPOSIT | C26: COMPLETED | D26: ALTA RENTABILIDAD SA DE CV | E26: ALTA RENTABILIDAD FACT 32 | F26: 37700 | G26: MXN | H26: 17.4364 | I26: 2162.15 | J26: USDC | K26: 0 | L26: USDC | M26: 0 | N26: USDC | O26: 3024.26 | P26: XXXX | Q26: XXXX | R26: XXXX | S26: 46231.871 | T26: =YEAR(A26) -> 2026 | U26: =MONTH(A26) -> 7 | V26: =VLOOKUP(U26,Dictionary_v2!$O$3:$P$15,2,0) -> 3 | W26: =VLOOKUP($D26,Dictionary_v2!$G:$J,2,0) -> P&L | X26: Recurring | Y26: =VLOOKUP($D26,Dictionary_v2!$G:$J,3,0) -> 1. Collections | Z26: =VLOOKUP(Y26,Dictionary_v2!R:S,2,0) -> 1. Collections | AA26: =VLOOKUP($D26,Dictionary_v2!$G:$J,4,0) -> 1. Full Stack | AB26: =if(F26>0,"In","Out") -> In | AC26: =VLOOKUP(C26,Dictionary_v2!L:M,2,0) -> Sent
A27: 46230.972 | B27: WITHDRAW | C27: COMPLETED | D27: Morgan Philips Mexico | E27: Factura 2768 | F27: -11310 | G27: MXN | H27: 17.4526 | I27: -648.04 | J27: USDC | K27: 0 | L27: USDC | M27: 0 | N27: USDC | O27: 862.12 | P27: XXXX | Q27: XXXX | R27: XXXX | S27: 46230.973 | T27: =YEAR(A27) -> 2026 | U27: =MONTH(A27) -> 7 | V27: =VLOOKUP(U27,Dictionary_v2!$O$3:$P$15,2,0) -> 3 | W27: =VLOOKUP($D27,Dictionary_v2!$G:$J,2,0) -> P&L | X27: Recurring | Y27: =VLOOKUP($D27,Dictionary_v2!$G:$J,3,0) -> 9.Sales comissions | Z27: =VLOOKUP(Y27,Dictionary_v2!R:S,2,0) -> #N/A | AA27: =VLOOKUP($D27,Dictionary_v2!$G:$J,4,0) -> 1. Partnerships | AB27: =if(F27>0,"In","Out") -> Out | AC27: =VLOOKUP(C27,Dictionary_v2!L:M,2,0) -> Sent
A28: 46224.949 | B28: CARD_PAYMENT | C28: COMPLETED | D28: Www.mirlo.mx Mexico | E28: WWW.MIRLO.MX | F28: -65.77 | G28: MXN | H28: 17.3948 | I28: -3.78 | J28: USDC | K28: 0 | L28: USDC | M28: 0 | N28: USDC | O28: 1510.16 | P28: 2535 | Q28: Ivan Amelong | R28: SERVICES | S28: 46226.375 | T28: =YEAR(A28) -> 2026 | U28: =MONTH(A28) -> 7 | V28: =VLOOKUP(U28,Dictionary_v2!$O$3:$P$15,2,0) -> 3 | W28: =VLOOKUP($D28,Dictionary_v2!$G:$J,2,0) -> P&L | X28: Recurring | Y28: =VLOOKUP($D28,Dictionary_v2!$G:$J,3,0) -> 3. Platform | Z28: =VLOOKUP(Y28,Dictionary_v2!R:S,2,0) -> 3. Platform | AA28: =VLOOKUP($D28,Dictionary_v2!$G:$J,4,0) -> 1. Variable | AB28: =if(F28>0,"In","Out") -> Out | AC28: =VLOOKUP(C28,Dictionary_v2!L:M,2,0) -> Sent
A29: 46224.875 | B29: WITHDRAW | C29: COMPLETED | D29: Nadia Meline Karaguezian | F29: -8342 | G29: MXN | H29: 17.3897 | I29: -479.71 | J29: USDC | K29: 0 | L29: USDC | M29: 0 | N29: USDC | O29: 1513.94 | P29: XXXX | Q29: XXXX | R29: XXXX | S29: 46224.876 | T29: =YEAR(A29) -> 2026 | U29: =MONTH(A29) -> 7 | V29: =VLOOKUP(U29,Dictionary_v2!$O$3:$P$15,2,0) -> 3 | W29: =VLOOKUP($D29,Dictionary_v2!$G:$J,2,0) -> P&L | X29: Recurring | Y29: =VLOOKUP($D29,Dictionary_v2!$G:$J,3,0) -> 8. Other fixed costs | Z29: =VLOOKUP(Y29,Dictionary_v2!R:S,2,0) -> 6. Other fixed and admin | AA29: =VLOOKUP($D29,Dictionary_v2!$G:$J,4,0) -> 4. Taxes | AB29: =if(F29>0,"In","Out") -> Out | AC29: =VLOOKUP(C29,Dictionary_v2!L:M,2,0) -> Sent
A30: 46212.947 | B30: CARD_PAYMENT | C30: COMPLETED | D30: Www.mirlo.mx Mexico | E30: WWW.MIRLO.MX | F30: -115.71 | G30: MXN | H30: 17.5243 | I30: -6.6 | J30: USDC | K30: 0 | L30: USDC | M30: 0 | N30: USDC | O30: 1993.65 | P30: 2535 | Q30: Ivan Amelong | R30: SERVICES | S30: 46214.375 | T30: =YEAR(A30) -> 2026 | U30: =MONTH(A30) -> 7 | V30: =VLOOKUP(U30,Dictionary_v2!$O$3:$P$15,2,0) -> 3 | W30: =VLOOKUP($D30,Dictionary_v2!$G:$J,2,0) -> P&L | X30: Recurring | Y30: =VLOOKUP($D30,Dictionary_v2!$G:$J,3,0) -> 3. Platform | Z30: =VLOOKUP(Y30,Dictionary_v2!R:S,2,0) -> 3. Platform | AA30: =VLOOKUP($D30,Dictionary_v2!$G:$J,4,0) -> 1. Variable | AB30: =if(F30>0,"In","Out") -> Out | AC30: =VLOOKUP(C30,Dictionary_v2!L:M,2,0) -> Sent
A31: 46212.931 | B31: DEPOSIT | C31: COMPLETED | D31: CLICOH EXPRESS MX SA DE CV | E31: CONTRATACION 9841 | F31: 28582.4 | G31: MXN | H31: 17.546 | I31: 1629 | J31: USDC | K31: 0 | L31: USDC | M31: 0 | N31: USDC | O31: 2000.25 | P31: XXXX | Q31: XXXX | R31: XXXX | S31: 46212.931 | T31: =YEAR(A31) -> 2026 | U31: =MONTH(A31) -> 7 | V31: =VLOOKUP(U31,Dictionary_v2!$O$3:$P$15,2,0) -> 3 | W31: =VLOOKUP($D31,Dictionary_v2!$G:$J,2,0) -> P&L | X31: Recurring | Y31: =VLOOKUP($D31,Dictionary_v2!$G:$J,3,0) -> 1. Collections | Z31: =VLOOKUP(Y31,Dictionary_v2!R:S,2,0) -> 1. Collections | AA31: =VLOOKUP($D31,Dictionary_v2!$G:$J,4,0) -> 1. Full Stack | AB31: =if(F31>0,"In","Out") -> In | AC31: =VLOOKUP(C31,Dictionary_v2!L:M,2,0) -> Sent
A32: 46207.176 | B32: CARD_PAYMENT | C32: COMPLETED | D32: T1 Telcel Pyre Ciudad De Mex | E32: Telcel | F32: -50 | G32: MXN | H32: 17.4519 | I32: -2.87 | J32: USDC | K32: 0 | L32: USDC | M32: 0 | N32: USDC | O32: 371.25 | P32: 2535 | Q32: Ivan Amelong | R32: SERVICES | S32: 46208.375 | T32: =YEAR(A32) -> 2026 | U32: =MONTH(A32) -> 7 | V32: =VLOOKUP(U32,Dictionary_v2!$O$3:$P$15,2,0) -> 3 | W32: =VLOOKUP($D32,Dictionary_v2!$G:$J,2,0) -> P&L | X32: Recurring | Y32: =VLOOKUP($D32,Dictionary_v2!$G:$J,3,0) -> 3. Platform | Z32: =VLOOKUP(Y32,Dictionary_v2!R:S,2,0) -> 3. Platform | AA32: =VLOOKUP($D32,Dictionary_v2!$G:$J,4,0) -> 1. Variable | AB32: =if(F32>0,"In","Out") -> Out | AC32: =VLOOKUP(C32,Dictionary_v2!L:M,2,0) -> Sent
A33: 46206.96 | B33: DEPOSIT | C33: COMPLETED | D33: AZUCENA DANAE MORALES MARTINEZ | E33: MERCADO*PAGO | F33: 4216.6 | G33: MXN | H33: 17.4819 | I33: 241.2 | J33: USDC | K33: 0 | L33: USDC | M33: 0 | N33: USDC | O33: 374.12 | P33: XXXX | Q33: XXXX | R33: XXXX | S33: 46206.96 | T33: =YEAR(A33) -> 2026 | U33: =MONTH(A33) -> 7 | V33: =VLOOKUP(U33,Dictionary_v2!$O$3:$P$15,2,0) -> 3 | W33: =VLOOKUP($D33,Dictionary_v2!$G:$J,2,0) -> P&L | X33: Recurring | Y33: =VLOOKUP($D33,Dictionary_v2!$G:$J,3,0) -> 1. Collections | Z33: =VLOOKUP(Y33,Dictionary_v2!R:S,2,0) -> 1. Collections | AA33: =VLOOKUP($D33,Dictionary_v2!$G:$J,4,0) -> 2. SaaS | AB33: =if(F33>0,"In","Out") -> In | AC33: =VLOOKUP(C33,Dictionary_v2!L:M,2,0) -> Sent
A34: 46206.694 | B34: CARD_PAYMENT | C34: COMPLETED | D34: Payu *google Ope D M Miguel Hidalg | E34: Google | F34: -2346.04 | G34: MXN | H34: 17.4739 | I34: -134.26 | J34: USDC | K34: 0 | L34: USDC | M34: 0 | N34: USDC | O34: 371.25 | P34: 2535 | Q34: Ivan Amelong | R34: SERVICES | S34: 46209.375 | T34: =YEAR(A34) -> 2026 | U34: =MONTH(A34) -> 7 | V34: =VLOOKUP(U34,Dictionary_v2!$O$3:$P$15,2,0) -> 3 | W34: =VLOOKUP($D34,Dictionary_v2!$G:$J,2,0) -> P&L | X34: Recurring | Y34: =VLOOKUP($D34,Dictionary_v2!$G:$J,3,0) -> 2. Candidates Sourcing | Z34: =VLOOKUP(Y34,Dictionary_v2!R:S,2,0) -> 2. Candidates Sourcing | AA34: =VLOOKUP($D34,Dictionary_v2!$G:$J,4,0) -> 1. Social media | AB34: =if(F34>0,"In","Out") -> Out | AC34: =VLOOKUP(C34,Dictionary_v2!L:M,2,0) -> Sent
A35: 46206.694 | B35: CARD_PAYMENT | C35: COMPLETED | D35: Payu *google Ope D M Miguel Hidalg | E35: Google | F35: -2346.04 | G35: MXN | H35: 17.4739 | I35: -134.26 | J35: USDC | K35: 0 | L35: USDC | M35: 0 | N35: USDC | O35: 371.25 | P35: 2535 | Q35: Ivan Amelong | R35: SERVICES | S35: 46209.375 | T35: =YEAR(A35) -> 2026 | U35: =MONTH(A35) -> 7 | V35: =VLOOKUP(U35,Dictionary_v2!$O$3:$P$15,2,0) -> 3 | W35: =VLOOKUP($D35,Dictionary_v2!$G:$J,2,0) -> P&L | X35: Recurring | Y35: =VLOOKUP($D35,Dictionary_v2!$G:$J,3,0) -> 2. Candidates Sourcing | Z35: =VLOOKUP(Y35,Dictionary_v2!R:S,2,0) -> 2. Candidates Sourcing | AA35: =VLOOKUP($D35,Dictionary_v2!$G:$J,4,0) -> 1. Social media | AB35: =if(F35>0,"In","Out") -> Out | AC35: =VLOOKUP(C35,Dictionary_v2!L:M,2,0) -> Sent
A36: 46206.032 | B36: WITHDRAW | C36: COMPLETED | D36: WeWork Mexico Co S. de R.L. de C.V | E36: Julio 2026 | F36: -10566.44 | G36: MXN | H36: 17.4785 | I36: -604.54 | J36: USDC | K36: 0 | L36: USDC | M36: 0 | N36: USDC | O36: 401.44 | P36: XXXX | Q36: XXXX | R36: XXXX | S36: 46206.033 | T36: =YEAR(A36) -> 2026 | U36: =MONTH(A36) -> 7 | V36: =VLOOKUP(U36,Dictionary_v2!$O$3:$P$15,2,0) -> 3 | W36: =VLOOKUP($D36,Dictionary_v2!$G:$J,2,0) -> P&L | X36: Recurring | Y36: =VLOOKUP($D36,Dictionary_v2!$G:$J,3,0) -> 8. Other fixed costs | Z36: =VLOOKUP(Y36,Dictionary_v2!R:S,2,0) -> 6. Other fixed and admin | AA36: =VLOOKUP($D36,Dictionary_v2!$G:$J,4,0) -> 3. Rent | AB36: =if(F36>0,"In","Out") -> Out | AC36: =VLOOKUP(C36,Dictionary_v2!L:M,2,0) -> Sent
A37: 46205.428 | B37: CARD_PAYMENT | C37: COMPLETED | D37: Indeed Iei26-01998749 Dublin | E37: Indeed IEI26-01998749 | F37: -6350.49 | G37: MXN | H37: 17.5457 | I37: -361.94 | J37: USDC | K37: 0 | L37: USDC | M37: 0 | N37: USDC | O37: 371.25 | P37: 2535 | Q37: Ivan Amelong | R37: SERVICES | S37: 46207.375 | T37: =YEAR(A37) -> 2026 | U37: =MONTH(A37) -> 7 | V37: =VLOOKUP(U37,Dictionary_v2!$O$3:$P$15,2,0) -> 3 | W37: =VLOOKUP($D37,Dictionary_v2!$G:$J,2,0) -> P&L | X37: Recurring | Y37: =VLOOKUP($D37,Dictionary_v2!$G:$J,3,0) -> 2. Candidates Sourcing | Z37: =VLOOKUP(Y37,Dictionary_v2!R:S,2,0) -> 2. Candidates Sourcing | AA37: =VLOOKUP($D37,Dictionary_v2!$G:$J,4,0) -> 2. Job Portals | AB37: =if(F37>0,"In","Out") -> Out | AC37: =VLOOKUP(C37,Dictionary_v2!L:M,2,0) -> Sent
A38: 46204.251 | B38: CASHBACK | C38: COMPLETED | D38: Cashback | E38: Cashback payment | F38: 1.64 | G38: USDC | H38: 1 | I38: 1.64 | J38: USDC | K38: 0 | L38: USDC | M38: 0 | N38: USDC | O38: 1367.92 | P38: XXXX | Q38: XXXX | R38: XXXX | S38: 46204.251 | T38: =YEAR(A38) -> 2026 | U38: =MONTH(A38) -> 7 | V38: =VLOOKUP(U38,Dictionary_v2!$O$3:$P$15,2,0) -> 3 | W38: =VLOOKUP($D38,Dictionary_v2!$G:$J,2,0) -> P&L | X38: Recurring | Y38: =VLOOKUP($D38,Dictionary_v2!$G:$J,3,0) -> 2. Candidates Sourcing | Z38: =VLOOKUP(Y38,Dictionary_v2!R:S,2,0) -> 2. Candidates Sourcing | AA38: =VLOOKUP($D38,Dictionary_v2!$G:$J,4,0) -> 2. Job Portals | AB38: =if(F38>0,"In","Out") -> In | AC38: =VLOOKUP(C38,Dictionary_v2!L:M,2,0) -> Sent
A39: 46202.988 | B39: WITHDRAW | C39: COMPLETED | D39: Federico David Naides | F39: -36429.15 | G39: MXN | H39: 17.4654 | I39: -2085.79 | J39: USDC | K39: 0 | L39: USDC | M39: 0 | N39: USDC | O39: 1366.28 | P39: XXXX | Q39: XXXX | R39: XXXX | S39: 46202.988 | T39: =YEAR(A39) -> 2026 | U39: =MONTH(A39) -> 6 | V39: =VLOOKUP(U39,Dictionary_v2!$O$3:$P$15,2,0) -> 2 | W39: =VLOOKUP($D39,Dictionary_v2!$G:$J,2,0) -> P&L | X39: Recurring | Y39: =VLOOKUP($D39,Dictionary_v2!$G:$J,3,0) -> 7. Founders | Z39: =VLOOKUP(Y39,Dictionary_v2!R:S,2,0) -> 6. Other fixed and admin | AA39: =VLOOKUP($D39,Dictionary_v2!$G:$J,4,0) -> 1. Salaries | AB39: =if(F39>0,"In","Out") -> Out | AC39: =VLOOKUP(C39,Dictionary_v2!L:M,2,0) -> Sent
A40: 46202.988 | B40: WITHDRAW | C40: COMPLETED | D40: Ivan Amelong | F40: -36429.15 | G40: MXN | H40: 17.4668 | I40: -2085.62 | J40: USDC | K40: 0 | L40: USDC | M40: 0 | N40: USDC | O40: 3452.07 | P40: XXXX | Q40: XXXX | R40: XXXX | S40: 46202.988 | T40: =YEAR(A40) -> 2026 | U40: =MONTH(A40) -> 6 | V40: =VLOOKUP(U40,Dictionary_v2!$O$3:$P$15,2,0) -> 2 | W40: =VLOOKUP($D40,Dictionary_v2!$G:$J,2,0) -> P&L | X40: Recurring | Y40: =VLOOKUP($D40,Dictionary_v2!$G:$J,3,0) -> 7. Founders | Z40: =VLOOKUP(Y40,Dictionary_v2!R:S,2,0) -> 6. Other fixed and admin | AA40: =VLOOKUP($D40,Dictionary_v2!$G:$J,4,0) -> 1. Salaries | AB40: =if(F40>0,"In","Out") -> Out | AC40: =VLOOKUP(C40,Dictionary_v2!L:M,2,0) -> Sent
...

Sheet Consolidated
B1: Year | C1: Month | D1: Quarter | E1: Statement | F1: Type | G1: Type 2 | H1: Type 2_B | I1: Type 3 | J1: Type 4 | K1: Description | L1: Amount | M1: Status | N1: Account
B2: =Mercury!Y3 -> 2026 | C2: =Mercury!AA3 -> 8 | D2: =Mercury!AB3 -> 3 | E2: =Mercury!AC3 -> P&L | F2: =Mercury!AD3 -> Recurring | G2: =Mercury!AE3 -> 2. Candidates Sourcing | H2: =Mercury!AF3 -> 2. Candidates Sourcing | I2: =Mercury!AG3 -> 1. Social Media | J2: =Mercury!AI3 -> In | K2: =Mercury!B3 -> Mercury IO Cashback | L2: =Mercury!C3 -> 131.38 | M2: =Mercury!D3 -> Sent | N2: Mercury
B3: =Mercury!Y4 -> 2026 | C3: =Mercury!AA4 -> 8 | D3: =Mercury!AB4 -> 3 | E3: =Mercury!AC4 -> Intercompany | F3: =Mercury!AD4 -> Recurring | G3: =Mercury!AE4 | H3: =Mercury!AF4 | I3: =Mercury!AG4 | J3: =Mercury!AI4 -> In | K3: =Mercury!B4 -> Welcome to Column N.A. (Mercury Checking xx5998) | L3: =Mercury!C4 -> 8777.25 | M3: =Mercury!D4 -> Sent | N3: Mercury
B4: =Mercury!Y5 -> 2026 | C4: =Mercury!AA5 -> 8 | D4: =Mercury!AB5 -> 3 | E4: =Mercury!AC5 -> Intercompany | F4: =Mercury!AD5 -> Recurring | G4: =Mercury!AE5 | H4: =Mercury!AF5 | I4: =Mercury!AG5 | J4: =Mercury!AI5 -> Out | K4: =Mercury!B5 -> Mercury Credit | L4: =Mercury!C5 -> -8777.25 | M4: =Mercury!D5 -> Sent | N4: Mercury
B5: =Mercury!Y6 -> 2026 | C5: =Mercury!AA6 -> 8 | D5: =Mercury!AB6 -> 3 | E5: =Mercury!AC6 -> P&L | F5: =Mercury!AD6 -> Recurring | G5: =Mercury!AE6 -> 3. Platform | H5: =Mercury!AF6 -> 3. Platform | I5: =Mercury!AG6 -> 1. Variable | J5: =Mercury!AI6 -> Out | K5: =Mercury!B6 -> Anthropic | L5: =Mercury!C6 -> -90.02 | M5: =Mercury!D6 -> Sent | N5: Mercury
B6: =Mercury!Y7 -> 2026 | C6: =Mercury!AA7 -> 8 | D6: =Mercury!AB7 -> 3 | E6: =Mercury!AC7 -> P&L | F6: =Mercury!AD7 -> Recurring | G6: =Mercury!AE7 -> 2. Candidates Sourcing | H6: =Mercury!AF7 -> 2. Candidates Sourcing | I6: =Mercury!AG7 -> 1. Social media | J6: =Mercury!AI7 -> Out | K6: =Mercury!B7 -> Facebook | L6: =Mercury!C7 -> -48.95 | M6: =Mercury!D7 -> Sent | N6: Mercury
B7: =Mercury!Y8 -> 2026 | C7: =Mercury!AA8 -> 8 | D7: =Mercury!AB8 -> 3 | E7: =Mercury!AC8 -> P&L | F7: =Mercury!AD8 -> Recurring | G7: =Mercury!AE8 -> 7. Founders | H7: =Mercury!AF8 -> 6. Other fixed and admin | I7: =Mercury!AG8 -> 1. Salaries | J7: =Mercury!AI8 -> Out | K7: =Mercury!B8 -> Ivan Amelong - Wise (Ivan Amelong) | L7: =Mercury!C8 -> -5500 | M7: =Mercury!D8 -> Sent | N7: Mercury
B8: =Mercury!Y9 -> 2026 | C8: =Mercury!AA9 -> 8 | D8: =Mercury!AB9 -> 3 | E8: =Mercury!AC9 -> P&L | F8: =Mercury!AD9 -> Recurring | G8: =Mercury!AE9 -> 7. Founders | H8: =Mercury!AF9 -> 6. Other fixed and admin | I8: =Mercury!AG9 -> 1. Salaries | J8: =Mercury!AI9 -> Out | K8: =Mercury!B9 -> Fede (BoA) (Federico David Naides) | L8: =Mercury!C9 -> -5500 | M8: =Mercury!D9 -> Sent | N8: Mercury
B9: =Mercury!Y10 -> 2026 | C9: =Mercury!AA10 -> 8 | D9: =Mercury!AB10 -> 3 | E9: =Mercury!AC10 -> P&L | F9: =Mercury!AD10 -> Recurring | G9: =Mercury!AE10 -> 3. Platform | H9: =Mercury!AF10 -> 3. Platform | I9: =Mercury!AG10 -> 2. Fixed | J9: =Mercury!AI10 -> Out | K9: =Mercury!B10 -> Intl. Wire Fee | L9: =Mercury!C10 -> -15 | M9: =Mercury!D10 -> Sent | N9: Mercury
B10: =Mercury!Y11 -> 2026 | C10: =Mercury!AA11 -> 8 | D10: =Mercury!AB11 -> 3 | E10: =Mercury!AC11 -> P&L | F10: =Mercury!AD11 -> Recurring | G10: =Mercury!AE11 -> 7. Founders | H10: =Mercury!AF11 -> 6. Other fixed and admin | I10: =Mercury!AG11 -> 1. Salaries | J10: =Mercury!AI11 -> Out | K10: =Mercury!B11 -> Efren (Ecuador) (Efren Rogelio Narvaez Peña) | L10: =Mercury!C11 -> -5000 | M10: =Mercury!D11 -> Sent | N10: Mercury
B11: =Mercury!Y12 -> 2026 | C11: =Mercury!AA12 -> 8 | D11: =Mercury!AB12 -> 3 | E11: =Mercury!AC12 -> Intercompany | F11: =Mercury!AD12 -> Recurring | G11: =Mercury!AE12 | H11: =Mercury!AF12 | I11: =Mercury!AG12 | J11: =Mercury!AI12 -> Out | K11: =Mercury!B12 -> Welcome to Column N.A. (Mercury Checking xx5998) | L11: =Mercury!C12 -> -11585.8 | M11: =Mercury!D12 -> Sent | N11: Mercury
B12: =Mercury!Y13 -> 2026 | C12: =Mercury!AA13 -> 8 | D12: =Mercury!AB13 -> 3 | E12: =Mercury!AC13 -> Intercompany | F12: =Mercury!AD13 -> Recurring | G12: =Mercury!AE13 | H12: =Mercury!AF13 | I12: =Mercury!AG13 | J12: =Mercury!AI13 -> In | K12: =Mercury!B13 -> Mercury Checking xx0301 | L12: =Mercury!C13 -> 11585.8 | M12: =Mercury!D13 -> Sent | N12: Mercury
B13: =Mercury!Y14 -> 2026 | C13: =Mercury!AA14 -> 8 | D13: =Mercury!AB14 -> 3 | E13: =Mercury!AC14 -> Intercompany | F13: =Mercury!AD14 -> Recurring | G13: =Mercury!AE14 | H13: =Mercury!AF14 | I13: =Mercury!AG14 | J13: =Mercury!AI14 -> Out | K13: =Mercury!B14 -> Welcome to Column N.A. (Mercury Checking xx5998) | L13: =Mercury!C14 -> -19000 | M13: =Mercury!D14 -> Sent | N13: Mercury
... B1369: =Mercury!Y1370 -> 2025 | C1369: =Mercury!AA1370 -> 1 | D1369: =Mercury!AB1370 -> 1 | E1369: =Mercury!AC1370 -> BS | F1369: =Mercury!AD1370 -> One-off | G1369: =Mercury!AE1370 -> 0. Investments | H1369: =Mercury!AF1370 -> 0. Investments | I1369: =Mercury!AG1370 -> 2. Founders | J1369: =Mercury!AI1370 -> In | K1369: =Mercury!B1370 -> Ivan Amelong - Wise (Ivan Amelong) | L1369: =Mercury!C1370 -> 1000 | M1369: =Mercury!D1370 -> Sent | N1369: Mercury
B1370: =DolarApp!T2 -> 2026 | C1370: =DolarApp!U2 -> 8 | D1370: =DolarApp!V2 -> 3 | E1370: =DolarApp!W2 -> P&L | F1370: =DolarApp!X2 -> Recurring | G1370: =DolarApp!Y2 -> 7. Founders | H1370: =DolarApp!Z2 -> 6. Other fixed and admin | I1370: =DolarApp!AA2 -> 1. Salaries | J1370: =DolarApp!AB2 -> Out | K1370: =DolarApp!D2 -> Ivan Amelong | L1370: =DolarApp!I2 -> -840.88 | M1370: =DolarApp!AC2 -> Sent | N1370: DolarApp
B1371: =DolarApp!T3 -> 2026 | C1371: =DolarApp!U3 -> 8 | D1371: =DolarApp!V3 -> 3 | E1371: =DolarApp!W3 -> P&L | F1371: =DolarApp!X3 -> Recurring | G1371: =DolarApp!Y3 -> 7. Founders | H1371: =DolarApp!Z3 -> 6. Other fixed and admin | I1371: =DolarApp!AA3 -> 1. Salaries | J1371: =DolarApp!AB3 -> Out | K1371: =DolarApp!D3 -> Federico David Naides | L1371: =DolarApp!I3 -> -840.88 | M1371: =DolarApp!AC3 -> Sent | N1371: DolarApp
